Traceback (most recent call last):
  File "/home/danbot/Documents/code/data_analysis/lib/python3.8/site-packages/jupyter_cache/executors/utils.py", line 51, in single_nb_execution
    executenb(
  File "/home/danbot/Documents/code/data_analysis/lib/python3.8/site-packages/nbclient/client.py", line 1082, in execute
    return NotebookClient(nb=nb, resources=resources, km=km, **kwargs).execute()
  File "/home/danbot/Documents/code/data_analysis/lib/python3.8/site-packages/nbclient/util.py", line 74, in wrapped
    return just_run(coro(*args, **kwargs))
  File "/home/danbot/Documents/code/data_analysis/lib/python3.8/site-packages/nbclient/util.py", line 53, in just_run
    return loop.run_until_complete(coro)
  File "/usr/lib/python3.8/asyncio/base_events.py", line 616, in run_until_complete
    return future.result()
  File "/home/danbot/Documents/code/data_analysis/lib/python3.8/site-packages/nbclient/client.py", line 535, in async_execute
    await self.async_execute_cell(
  File "/home/danbot/Documents/code/data_analysis/lib/python3.8/site-packages/nbclient/client.py", line 827, in async_execute_cell
    self._check_raise_for_error(cell, exec_reply)
  File "/home/danbot/Documents/code/data_analysis/lib/python3.8/site-packages/nbclient/client.py", line 735, in _check_raise_for_error
    raise CellExecutionError.from_cell_and_msg(cell, exec_reply['content'])
nbclient.exceptions.CellExecutionError: An error occurred while executing the following cell:
------------------
fig, ax = plt.subplots(1, 1, figsize=(8, 6))
# evaluate a range of digital content growth rates
for f in growth_rates:
    bits = [bits_estimation(y, f, N_b) for y in years]
    
    ax.plot(years, bits, label=f)
    
ax.set_xscale('log',base=10) 
# ax.set_yscale('log',base=10) 
ax.set_ylabel('Annual Info. Production [log10(bits)]')
ax.set_xlabel('Years from Present [log10 scale]')
ax.legend()
plt.show()  
------------------

[0;31m---------------------------------------------------------------------------[0m
[0;31mNameError[0m                                 Traceback (most recent call last)
[0;32m<ipython-input-4-cc034608b4e6>[0m in [0;36m<module>[0;34m[0m
[1;32m      2[0m [0;31m# evaluate a range of digital content growth rates[0m[0;34m[0m[0;34m[0m[0;34m[0m[0m
[1;32m      3[0m [0;32mfor[0m [0mf[0m [0;32min[0m [0mgrowth_rates[0m[0;34m:[0m[0;34m[0m[0;34m[0m[0m
[0;32m----> 4[0;31m     [0mbits[0m [0;34m=[0m [0;34m[[0m[0mbits_estimation[0m[0;34m([0m[0my[0m[0;34m,[0m [0mf[0m[0;34m,[0m [0mN_b[0m[0;34m)[0m [0;32mfor[0m [0my[0m [0;32min[0m [0myears[0m[0;34m][0m[0;34m[0m[0;34m[0m[0m
[0m[1;32m      5[0m [0;34m[0m[0m
[1;32m      6[0m     [0max[0m[0;34m.[0m[0mplot[0m[0;34m([0m[0myears[0m[0;34m,[0m [0mbits[0m[0;34m,[0m [0mlabel[0m[0;34m=[0m[0mf[0m[0;34m)[0m[0;34m[0m[0;34m[0m[0m

[0;32m<ipython-input-4-cc034608b4e6>[0m in [0;36m<listcomp>[0;34m(.0)[0m
[1;32m      2[0m [0;31m# evaluate a range of digital content growth rates[0m[0;34m[0m[0;34m[0m[0;34m[0m[0m
[1;32m      3[0m [0;32mfor[0m [0mf[0m [0;32min[0m [0mgrowth_rates[0m[0;34m:[0m[0;34m[0m[0;34m[0m[0m
[0;32m----> 4[0;31m     [0mbits[0m [0;34m=[0m [0;34m[[0m[0mbits_estimation[0m[0;34m([0m[0my[0m[0;34m,[0m [0mf[0m[0;34m,[0m [0mN_b[0m[0;34m)[0m [0;32mfor[0m [0my[0m [0;32min[0m [0myears[0m[0;34m][0m[0;34m[0m[0;34m[0m[0m
[0m[1;32m      5[0m [0;34m[0m[0m
[1;32m      6[0m     [0max[0m[0;34m.[0m[0mplot[0m[0;34m([0m[0myears[0m[0;34m,[0m [0mbits[0m[0;34m,[0m [0mlabel[0m[0;34m=[0m[0mf[0m[0;34m)[0m[0;34m[0m[0;34m[0m[0m

[0;31mNameError[0m: name 'N_b' is not defined
NameError: name 'N_b' is not defined

