Traceback (most recent call last):
  File "/home/danbot/Documents/code/data_analysis/lib/python3.8/site-packages/jupyter_cache/executors/utils.py", line 51, in single_nb_execution
    executenb(
  File "/home/danbot/Documents/code/data_analysis/lib/python3.8/site-packages/nbclient/client.py", line 1112, in execute
    return NotebookClient(nb=nb, resources=resources, km=km, **kwargs).execute()
  File "/home/danbot/Documents/code/data_analysis/lib/python3.8/site-packages/nbclient/util.py", line 74, in wrapped
    return just_run(coro(*args, **kwargs))
  File "/home/danbot/Documents/code/data_analysis/lib/python3.8/site-packages/nbclient/util.py", line 53, in just_run
    return loop.run_until_complete(coro)
  File "/usr/lib/python3.8/asyncio/base_events.py", line 616, in run_until_complete
    return future.result()
  File "/home/danbot/Documents/code/data_analysis/lib/python3.8/site-packages/nbclient/client.py", line 553, in async_execute
    await self.async_execute_cell(
  File "/home/danbot/Documents/code/data_analysis/lib/python3.8/site-packages/nbclient/client.py", line 857, in async_execute_cell
    self._check_raise_for_error(cell, exec_reply)
  File "/home/danbot/Documents/code/data_analysis/lib/python3.8/site-packages/nbclient/client.py", line 760, in _check_raise_for_error
    raise CellExecutionError.from_cell_and_msg(cell, exec_reply_content)
nbclient.exceptions.CellExecutionError: An error occurred while executing the following cell:
------------------
stn_das = {'08MF065': 712,
          '08MH147': 290,
          '08MG001': 383}

# make a copy of the flow dataframe
lt_ur = lt_df.copy()
for stn in station_list:
    lt_ur[stn] = 1000 * lt_ur[stn] / stn_das[stn]
------------------

[0;31m---------------------------------------------------------------------------[0m
[0;31mNameError[0m                                 Traceback (most recent call last)
[0;32m<ipython-input-5-eb373570e1a4>[0m in [0;36m<module>[0;34m[0m
[1;32m      4[0m [0;34m[0m[0m
[1;32m      5[0m [0;31m# make a copy of the flow dataframe[0m[0;34m[0m[0;34m[0m[0;34m[0m[0m
[0;32m----> 6[0;31m [0mlt_ur[0m [0;34m=[0m [0mlt_df[0m[0;34m.[0m[0mcopy[0m[0;34m([0m[0;34m)[0m[0;34m[0m[0;34m[0m[0m
[0m[1;32m      7[0m [0;32mfor[0m [0mstn[0m [0;32min[0m [0mstation_list[0m[0;34m:[0m[0;34m[0m[0;34m[0m[0m
[1;32m      8[0m     [0mlt_ur[0m[0;34m[[0m[0mstn[0m[0;34m][0m [0;34m=[0m [0;36m1000[0m [0;34m*[0m [0mlt_ur[0m[0;34m[[0m[0mstn[0m[0;34m][0m [0;34m/[0m [0mstn_das[0m[0;34m[[0m[0mstn[0m[0;34m][0m[0;34m[0m[0;34m[0m[0m

[0;31mNameError[0m: name 'lt_df' is not defined
NameError: name 'lt_df' is not defined

