Traceback (most recent call last):
  File "/home/danbot/Documents/code/data_analysis/lib/python3.8/site-packages/jupyter_cache/executors/utils.py", line 51, in single_nb_execution
    executenb(
  File "/home/danbot/Documents/code/data_analysis/lib/python3.8/site-packages/nbclient/client.py", line 1112, in execute
    return NotebookClient(nb=nb, resources=resources, km=km, **kwargs).execute()
  File "/home/danbot/Documents/code/data_analysis/lib/python3.8/site-packages/nbclient/util.py", line 74, in wrapped
    return just_run(coro(*args, **kwargs))
  File "/home/danbot/Documents/code/data_analysis/lib/python3.8/site-packages/nbclient/util.py", line 53, in just_run
    return loop.run_until_complete(coro)
  File "/usr/lib/python3.8/asyncio/base_events.py", line 616, in run_until_complete
    return future.result()
  File "/home/danbot/Documents/code/data_analysis/lib/python3.8/site-packages/nbclient/client.py", line 553, in async_execute
    await self.async_execute_cell(
  File "/home/danbot/Documents/code/data_analysis/lib/python3.8/site-packages/nbclient/client.py", line 857, in async_execute_cell
    self._check_raise_for_error(cell, exec_reply)
  File "/home/danbot/Documents/code/data_analysis/lib/python3.8/site-packages/nbclient/client.py", line 760, in _check_raise_for_error
    raise CellExecutionError.from_cell_and_msg(cell, exec_reply_content)
nbclient.exceptions.CellExecutionError: An error occurred while executing the following cell:
------------------
# retrive long-term data pre-saved in the data folder

lt_dfs = []
for stn in station_list:
    # I saved long-term data ahead of time in the 'data/' folder
    filename = f'data/{stn}.csv'
    
    df = pd.read_csv(filename, header=13,
                  parse_dates=['Datetime'], index_col='Datetime',
                 infer_datetime_format=True)
    
    # how many analysis types are there?
    df.head()
------------------

[0;31m---------------------------------------------------------------------------[0m
[0;31mNameError[0m                                 Traceback (most recent call last)
[0;32m<ipython-input-10-00451bbd78d2>[0m in [0;36m<module>[0;34m[0m
[1;32m      2[0m [0;34m[0m[0m
[1;32m      3[0m [0mlt_dfs[0m [0;34m=[0m [0;34m[[0m[0;34m][0m[0;34m[0m[0;34m[0m[0m
[0;32m----> 4[0;31m [0;32mfor[0m [0mstn[0m [0;32min[0m [0mstation_list[0m[0;34m:[0m[0;34m[0m[0;34m[0m[0m
[0m[1;32m      5[0m     [0;31m# I saved long-term data ahead of time in the 'data/' folder[0m[0;34m[0m[0;34m[0m[0;34m[0m[0m
[1;32m      6[0m     [0mfilename[0m [0;34m=[0m [0;34mf'data/{stn}.csv'[0m[0;34m[0m[0;34m[0m[0m

[0;31mNameError[0m: name 'station_list' is not defined
NameError: name 'station_list' is not defined

